<h1>nested_exception (C++11)</h1>
<p><pre class="codehilite"><code class="language-cpp"><span style="color: #000">namespace std {
  class nested_exception;
}</span></code></pre>
</p>
<h2>概要</h2>
<p><code><span style="color: #000">nested_exception</span></code>クラスは、例外を階層構造として処理する場合に、元の例外を一時的に保持した状態で、別の例外として送出するための使用する。入れ子になった例外を補足した場合、<a href="http://cpprefjp.github.io/reference/exception/nested_exception/rethrow_nested.html"><code><span style="color: #000">rethrow_nested()</span></code></a>メンバ関数を呼び出すことで、元の例外を送出できる。</p>
<h3>メンバ関数</h3>
<table border="1" bordercolor="#888" style="border-collapse:collapse">
<thead>
<tr>
<th></th>
<th></th>
</tr>
</thead>
<tbody>
<tr>
<td><a href="http://cpprefjp.github.io/reference/exception/nested_exception/nested_exception.html"><code><span style="color: #000">(constructor)</span></code></a></td>
<td>コンストラクタ</td>
</tr>
<tr>
<td><code><span style="color: #000">~virtual nested_exception() = default;</span></code></td>
<td>デストラクタ</td>
</tr>
<tr>
<td><code><span style="color: #000">nested_exception&amp; operator=(const nested_exception&amp;) = default;</span></code></td>
<td>代入演算子</td>
</tr>
<tr>
<td><a href="http://cpprefjp.github.io/reference/exception/nested_exception/rethrow_nested.html"><code><span style="color: #000">rethrow_nested</span></code></a></td>
<td>入れ子になった例外を送出する</td>
</tr>
<tr>
<td><a href="http://cpprefjp.github.io/reference/exception/nested_exception/nested_ptr.html"><code><span style="color: #000">nested_ptr</span></code></a></td>
<td>入れ子になった例外へのポインタを取得する</td>
</tr>
</tbody>
</table>
<h3>例</h3>
<p><pre class="codehilite"><code class="language-cpp"><span style="color: #000">#include &lt;exception&gt;
#include &lt;iostream&gt;

class my_exception : public std::nested_exception {};

int main()
{
  try {
    try {
      try {
        throw 1; // int値を送出
      }
      catch (int&amp; x) {
        std::cout &lt;&lt; "1st caught: " &lt;&lt; x &lt;&lt; std::endl;
        throw my_exception(); // 現在の例外(int)を入れ子にしてmy_exceptionを送出
      }
    }
    catch (my_exception&amp; e) {
      std::cout &lt;&lt; "2nd caught: my_exception(nested_exception)." &lt;&lt; std::endl;
      // 入れ子になっている例外(int)を送出
      e.rethrow_nested();
    }
  }
  catch (int&amp; x) {
    std::cout &lt;&lt; "3rd caught: " &lt;&lt; x &lt;&lt; std::endl;
  }
}</span></code></pre>
</p>
<h3>出力</h3>
<p><pre><code><span style="color: #000">1st caught: 1
2nd caught: my_exception(nested_exception).
3rd caught: 1
</span></code></pre></p>
<h2>バージョン</h2>
<h3>言語</h3>
<ul>
<li>C++11</li>
</ul>
<h3>処理系</h3>
<ul>
<li><a href="http://cpprefjp.github.io/implementation.html#clang">Clang</a>: ??</li>
<li><a href="http://cpprefjp.github.io/implementation.html#gcc">GCC</a>: </li>
<li><a href="http://cpprefjp.github.io/implementation.html#gcc">GCC, C++0x mode</a>: 4.7.0</li>
<li><a href="http://cpprefjp.github.io/implementation.html#icc">ICC</a>: ??</li>
<li><a href="http://cpprefjp.github.io/implementation.html#visual_cpp">Visual C++</a> ??</li>
</ul>
<h3>参照</h3>
<footer><a href="https://github.com/cpprefjp/site/edit/master/reference/exception/nested_exception.md" target="_blank">編集</a></footer>