<h1>set_exception (C++11)</h1>
<p><pre class="codehilite"><code class="language-cpp"><a href="http://cpprefjp.github.io/reference/exception/exception_ptr.html">exception_ptr</a> p);<span style="color: #000">void set_exception(</span></code></pre>
</p>
<h2>概要</h2>
<p>結果の例外を設定する</p>
<h2>効果</h2>
<p>例外ポインタ<code><span style="color: #000">p</span></code>をアトミックに共有状態に格納し、準備完了状態(<a href="http://cpprefjp.github.io/reference/future/future_status.html"><code><span style="color: #000">future_status::ready</span></code></a>)にする。</p>
<h2>戻り値</h2>
<p>なし</p>
<h2>例外</h2>
<p>この関数は、以下のerror conditionを持つ<a href="http://cpprefjp.github.io/reference/future/future_error.html"><code><span style="color: #000">future_error</span></code></a>例外オブジェクトを送出する可能性がある：</p>
<ul>
<li><a href="http://cpprefjp.github.io/reference/future/future_errc.html"><code><span style="color: #000">promise_already_satisfied</span></code></a> ： すでに値もしくは例外が設定されている</li>
<li><a href="http://cpprefjp.github.io/reference/future/future_errc.html"><code><span style="color: #000">no_state</span></code></a> ： <code><span style="color: #000">*this</span></code>が共有状態を持っていない(<code><span style="color: #000">promise</span></code>オブジェクトがムーブされると起こりうる)</li>
</ul>
<h2>例</h2>
<p><pre class="codehilite"><code class="language-cpp"><span style="color:#ff0000">set_exception</span>(ep);
  }
}

int main()
{
  std::promise&lt;int&gt; p;
  std::future&lt;int&gt; f = p.get_future();

  std::thread t(calc, std::move(p));

  try {
    int result = f.get(); // promiseで設定された例外が送出される
  }
  catch (std::invalid_argument&amp; e) {
    std::cout &lt;&lt; e.what() &lt;&lt; std::endl;
  }

  t.join();
}<span style="color: #000">#include &lt;iostream&gt;
#include &lt;future&gt;
#include &lt;thread&gt;
#include &lt;utility&gt;
#include &lt;stdexcept&gt;

void calc(std::promise&lt;int&gt; p)
{
  try {
    // 計算で何らかのエラーが発生した
    throw std::invalid_argument("invalid argument!");
  }
  catch (...) {
    // 呼び出し元スレッドに例外を設定する
    std::exception_ptr ep = std::current_exception();
    p.</span></code></pre>
</p>
<h3>出力</h3>
<p><pre><code><span style="color: #000">invalid argument!
</span></code></pre></p>
<h2>バージョン</h2>
<h3>言語</h3>
<ul>
<li>C++11</li>
</ul>
<h3>処理系</h3>
<ul>
<li><a href="http://cpprefjp.github.io/implementation.html#clang">Clang</a>: ??</li>
<li><a href="http://cpprefjp.github.io/implementation.html#gcc">GCC</a>: </li>
<li><a href="http://cpprefjp.github.io/implementation.html#gcc">GCC, C++0x mode</a>: 4.7.0</li>
<li><a href="http://cpprefjp.github.io/implementation.html#icc">ICC</a>: ??</li>
<li><a href="http://cpprefjp.github.io/implementation.html#visual_cpp">Visual C++</a>: 11.0</li>
</ul>
<h2>参照</h2>
<footer><a href="https://github.com/cpprefjp/site/edit/master/reference/future/promise/set_exception.md" target="_blank">編集</a></footer>