<h1>operator() (C++11)</h1>
<p><pre class="codehilite"><code class="language-cpp"><span style="color: #000">void operator()(ArgTypes... args);</span></code></pre>
</p>
<h2>概要</h2>
<p>タスクの実行し、戻り値を共有状態に格納する。</p>
<h2>効果</h2>
<p>メンバ変数として保持している関数オブジェクト<code><span style="color: #000">f</span></code>に対して<a href="http://cpprefjp.github.io/reference/functional/invoke.html"><code><span style="color: #000">INVOKE</span></code></a><code><span style="color: #000">(f, args..., R)</span></code>によって関数呼び出しを行い、その戻り値を<a href="http://cpprefjp.github.io/reference/future/future.html"><code><span style="color: #000">future</span></code></a>との共有状態に格納する。関数<code><span style="color: #000">f</span></code>の内部で例外が送出された場合は、共有状態に送出された例外が格納される。
共有状態が準備完了状態(<a href="http://cpprefjp.github.io/reference/future/future_status.html"><code><span style="color: #000">future_status::ready</span></code></a>)となる。</p>
<h2>戻り値</h2>
<p>なし</p>
<h2>例外</h2>
<p>この関数は、以下のerror conditionを持つ<a href="http://cpprefjp.github.io/reference/future/future_error.html"><code><span style="color: #000">future_error</span></code></a>例外オブジェクトを送出する可能性がある：</p>
<ul>
<li><a href="http://cpprefjp.github.io/reference/future/future_errc.html"><code><span style="color: #000">promise_already_satisfied</span></code></a> ： 格納されたタスクがすでに実行された</li>
<li><a href="http://cpprefjp.github.io/reference/future/packaged_task/future_errc.html"><code><span style="color: #000">no_state</span></code></a>： <code><span style="color: #000">*this</span></code>が共有状態を持っていない(<code><span style="color: #000">packaged_task</span></code>オブジェクトがムーブされると起こりうる)</li>
</ul>
<h2>例</h2>
<p><pre class="codehilite"><code class="language-cpp"><span style="color:#ff0000">task(2, 3);</span>

    // タスクの結果を取得
    int result = f.get();
    std::cout &lt;&lt; result &lt;&lt; std::endl;
  }

  // 例外を投げるタスク
  {
    std::packaged_task&lt;int()&gt; task(except_task);
    std::future&lt;int&gt; f = task.get_future();

    // タスクを実行する
    <span style="color:#ff0000">task()</span>;

    // タスクの結果を取得
    try {
      f.get();
    }
    catch (std::runtime_error&amp; e) {
      // タスク内で送出された例外を補足
      std::cout &lt;&lt; e.what() &lt;&lt; std::endl;
    }
  }
}<span style="color: #000">#include &lt;iostream&gt;
#include &lt;future&gt;
#include &lt;stdexcept&gt;

int plus_task(int a, int b)
{
  return a + b;
}

int except_task()
{
  throw std::runtime_error("error!");
}

int main()
{
  {
    std::packaged_task&lt;int(int, int)&gt; task(plus_task);
    std::future&lt;int&gt; f = task.get_future();

    // タスクを実行する
    </span></code></pre>
</p>
<h3>出力</h3>
<p><pre><code><span style="color: #000">5
error!
</span></code></pre></p>
<h2>バージョン</h2>
<h3>言語</h3>
<ul>
<li>C++11</li>
</ul>
<h3>処理系</h3>
<ul>
<li><a href="http://cpprefjp.github.io/implementation.html#clang">Clang</a>: ??</li>
<li><a href="http://cpprefjp.github.io/implementation.html#gcc">GCC</a>: </li>
<li><a href="http://cpprefjp.github.io/implementation.html#gcc">GCC, C++0x mode</a>: 4.7.0</li>
<li><a href="http://cpprefjp.github.io/implementation.html#icc">ICC</a>: ??</li>
<li><a href="http://cpprefjp.github.io/implementation.html#visual_cpp">Visual C++</a>: 11.0</li>
</ul>
<h2>参照</h2>
<footer><a href="https://github.com/cpprefjp/site/edit/master/reference/future/packaged_task/op_apply.md" target="_blank">編集</a></footer>